<mujoco model="arm3d">
    <compiler inertiafromgeom="true" angle="degree" coordinate="local"
    />
    <option timestep="0.005" gravity="0 0 -9.81" iterations="20" integrator="RK4" />

    <default>
<!--        <joint armature='0.04' damping="1" limited="true"/>-->
        <geom friction=".1 .1 .1" density="300" margin="0.002" condim="1" contype="0" conaffinity="0"/>
    </default>

    <asset>
        <texture builtin="gradient" height="100" rgb1="1 1 1" rgb2="0 0 0" type="skybox" width="100"/>
        <texture builtin="flat" height="1278" mark="cross" markrgb="1 1 1" name="texgeom" random="0.01" rgb1="0.8 0.6 0.4" rgb2="0.8 0.6 0.4" type="cube" width="127"/>
        <texture builtin="checker" height="100" name="texplane" rgb1="0 0 0" rgb2="0.8 0.8 0.8" type="2d" width="100"/>
        <material name="MatPlane" reflectance="0.5" shininess="1" specular="1" texrepeat="2 2" texture="texplane"/>
        <material name="geom" texture="texgeom" texuniform="true"/>

        <texture file="lightwood.png" type="cube" name="light-wood" />
        <material name="light-wood-mat" texture="light-wood" texrepeat="3 3" specular="0.4" shininess="0.1" />

        <mesh file="arm.stl" scale="0.001 0.001 0.001" />
        <mesh file="HS-488HB.stl" scale="0.001 0.001 0.001" />
        <mesh file="horn.stl" scale="0.001 0.001 0.001" />
        <mesh file="encoder_mount.stl" scale="0.001 0.001 0.001" />
        <mesh file="encoder.stl" scale="0.001 0.001 0.001" />
        <mesh file="pendulum_mount.stl" scale="0.001 0.001 0.001" />
        <mesh file="dowel.stl" scale="0.001 0.001 0.001" />
        <mesh file="pendulum_weight.stl" scale="0.001 0.001 0.001" />
    </asset>

    <worldbody>
        <light cutoff="100" diffuse="1 1 1" dir="-0 0 -1.3" directional="true" exponent="1" pos="0 0 1.3" specular=".1 .1 .1"/>
        <geom conaffinity="1" condim="3" material="MatPlane" name="floor" pos="0 0 -0.500" rgba="0.8 0.9 0.8 1" size="1 1 1" type="plane"/>

        <body name="pendulum_r" pos="0 0 0" euler="0 0 0">
            <geom name="servo" type="mesh" mesh="HS-488HB" pos="0 0 0" condim="1" rgba="0 0 0 1"/>

            <body name="arm" pos="0 0 0">
                <joint name="servo_joint" type="hinge" pos="0 -0.025 0" axis="0 0 1" range="-90.0 90.0" damping="1.0" limited="true" />

                <geom name="arm" type="mesh" mesh="arm" pos="0 0 0" condim="1" mass="0.125"/>
                <geom name="servo_horn" type="mesh" mesh="horn" pos="0 0 0" condim="1"  rgba="0.137 0.408 0.8 1" mass="0.004"/>

                <geom name="encoder_mount" type="mesh" mesh="encoder_mount" pos="0 0 0" rgba="1 0 0 1" mass="0.01"/>
                <geom name="encoder" type="mesh" mesh="encoder" pos="0 0 0" rgba="0 0 0 1" mass="0.017"/>

                <body name="pendulum" pos="0 0 0">
                    <joint name="encoder_joint" type="hinge" pos="0 -0.450 0.018" axis="0 -1 0" limited="false" damping="0.0015" />

                    <geom name="pendulum_coupler" type="mesh" mesh="pendulum_mount" pos="0 0 0"  rgba="1 0 0 1" mass="0.015"/>
                    <geom name="pine_dowel" type="mesh" mesh="dowel" pos="0 0 0" material="light-wood-mat" mass="0.011"/>
                    <geom name="pendulum_weight" type="mesh" mesh="pendulum_weight" pos="0 0 0"  rgba="1 0 0 1"  mass="0.009"/>
                </body>
            </body>


        </body>


    </worldbody>

    <actuator>
<!--        <position joint="servo_joint" ctrlrange="-2.0 2.0" kp="6" ctrllimited="true" name="servo_motor"/>-->
        <general joint="servo_joint" ctrlrange="-2.0 2.0"
                 biastype="affine"
                 dynprm="1 0 0" gainprm="6 0 0" biasprm="0 -6 0"
                 ctrllimited="true" name="servo_motor"/>
<!--        <position joint="encoder_joint" ctrlrange="-2.0 2.0" kp="3" ctrllimited="true" name="encoder_motor"/>-->
    </actuator>
    <sensor>
        <jointpos joint="encoder_joint" name="theta" />
        <jointvel joint="encoder_joint" name="angular_velocity" />
        <jointpos joint="servo_joint" name="servo_position" />
        <jointvel joint="servo_joint" name="servo_angular_velocity" />
    </sensor>
</mujoco>
